<?xml version="1.0" ?>
<robot name="drc_skeleton">
    <!-- Head Link Simple Collision Meshes -->
    <mujoco>
        <size njmax="5000" nconmax="2000" nstack="1000000000"/>
    </mujoco>
    <link name="world">
    </link>
    <link name="ground">
    	<collision>
                <origin rpy="0,0,0" xyz="0 0 -0.05"/>
                <geometry>
                    <box size="100 100 0.1"/>
                </geometry>
    	</collision>
    </link>
    <joint name="base_to_world_0" type="floating">
        <parent link="world"/>
        <child link="pelvis_0"/>
        <origin rpy="0 0 0" xyz="0 0 3.000000e-01"/>
    </joint>
    <link name="head_0">
        <inertial>
            <origin xyz="-0.075493 3.3383E-05 0.02774" rpy="0 0 0" />
            <mass value="1.41984" />
            <inertia iyy="0.0041178" ixy="-1.5797E-06" iyz="-6.8415E-07" ixx="0.0039688" ixz="-0.00089293" izz="0.0035243" />
        </inertial>
        <visual>
            <origin xyz="0 0 0" rpy="0 0 0" />
            <geometry>
                <mesh filename="head.stl" />
            </geometry>
            <material name="">
                <color rgba="0.9098 0.44314 0.031373 1" />
            </material>
        </visual>
    </link>
    <!-- Stereo Camera -->
    <joint name="left_camera_frame_joint_0" type="fixed">
        <!-- optical frame collocated with tilting DOF -->
        <origin xyz="0.0 0.035 -0.002"/>
        <parent link="head_0"/>
        <child link="left_camera_frame_0"/>
    </joint>
    <link name="left_camera_frame_0">
        <inertial>
            <mass value="1e-5" />
            <!-- collocate with parent link and remove mass from it -->
            <origin xyz="-0.075493 0.035033383 0.02574"/>
            <inertia ixx="1e-6" ixy="0" ixz="0" iyy="1e-6" iyz="0" izz="1e-6" />
        </inertial>
    </link>
    <joint name="left_camera_optical_frame_joint_0" type="fixed">
        <origin xyz="0 0 0" rpy="-1.5708 0.0 -1.5708" />
        <parent link="left_camera_frame_0" />
        <child link="left_camera_optical_frame_0"/>
    </joint>
    <link name="left_camera_optical_frame_0"/>
    <joint name="right_camera_frame_joint_0" type="fixed">
        <origin xyz="0.0 -0.035 -0.002"/>
        <parent link="head_0"/>
        <child link="right_camera_frame_0"/>
    </joint>
    <link name="right_camera_frame_0">
        <inertial>
            <mass value="1e-5" />
            <!-- collocate with parent link and remove mass from it -->
            <origin xyz="-0.075493 -0.034966617 0.02574"/>
            <inertia ixx="1e-6" ixy="0" ixz="0" iyy="1e-6" iyz="0" izz="1e-6" />
        </inertial>
    </link>
    <joint name="right_camera_optical_frame_joint_0" type="fixed">
        <origin xyz="0 0 0" rpy="-1.5708 0.0 -1.5708" />
        <parent link="right_camera_frame_0" />
        <child link="right_camera_optical_frame_0"/>
    </joint>
    <link name="right_camera_optical_frame_0"/>

    <joint name="center_top_led_frame_joint_0" type="fixed">
        <origin xyz="0.01125 0.0 0.0105"/>
        <parent link="head_0"/>
        <child link="center_top_led_frame_0"/>
    </joint>
    <link name="center_top_led_frame_0">
        <inertial>
            <mass value="1e-5" />
            <!-- collocate with parent link and remove mass from it -->
            <origin xyz="-0.064243 0.000033383 0.03824" rpy="0 0 0" />
            <inertia ixx="1e-6" ixy="0" ixz="0" iyy="1e-6" iyz="0" izz="1e-6" />
        </inertial>
    </link>
    <joint name="center_bottom_led_frame_joint_0" type="fixed">
        <origin xyz="0.01125 0.0 -0.0155"/>
        <parent link="head_0"/>
        <child link="center_bottom_led_frame_0"/>
    </joint>
    <link name="center_bottom_led_frame_0">
        <inertial>
            <mass value="1e-5" />
            <!-- collocate with parent link and remove mass from it -->
            <origin xyz="-0.064243 0.000033383 0.01224" rpy="0 0 0" />
            <inertia ixx="1e-6" ixy="0" ixz="0" iyy="1e-6" iyz="0" izz="1e-6" />
        </inertial>
    </link>
    <joint name="left_led_frame_joint_0" type="fixed">
        <origin xyz="-0.01443 0.07452 0.050346" rpy="0 -0.15 0.53"/>
        <parent link="head_0"/>
        <child link="left_led_frame_0"/>
    </joint>
    <link name="left_led_frame_0">
        <inertial>
            <mass value="1e-5" />
            <!-- collocate with parent link and remove mass from it -->
            <origin xyz="-0.089923 0.074553383 0.078086" rpy="0 -0.15 0.53" />
            <inertia ixx="1e-6" ixy="0" ixz="0" iyy="1e-6" iyz="0" izz="1e-6" />
        </inertial>
    </link>
    <joint name="right_led_frame_joint_0" type="fixed">
        <origin xyz="-0.01443 -0.07452 0.050346" rpy="0 -0.15 -0.53"/>
        <parent link="head_0"/>
        <child link="right_led_frame_0"/>
    </joint>
    <link name="right_led_frame_0">
        <inertial>
            <mass value="1e-5" />
            <!-- collocate with parent link and remove mass from it -->
            <origin xyz="-0.089923 -0.074486617 0.07908" rpy="0 -0.15 -0.53" />
            <inertia ixx="1e-6" ixy="0" ixz="0" iyy="1e-6" iyz="0" izz="1e-6" />
        </inertial>
    </link>

    <!-- imu link -->
    <link name="head_imu_link_0">
        <inertial>
            <mass value="1e-5" />
            <!-- collocate with parent link and remove mass from it -->
            <origin xyz="-0.122993 0.035033383 0.02774" rpy="0 0 0" />
            <inertia ixx="1e-6" ixy="0" ixz="0" iyy="1e-6" iyz="0" izz="1e-6" />
        </inertial>
        <visual>
            <origin rpy="0 0 0" xyz="0 0 0"/>
            <geometry>
                <box size="0.01 0.01 0.01"/>
            </geometry>
        </visual>
    </link>
    <joint name="head_imu_joint_0" type="fixed">
        <parent link="head_0"/>
        <child link="head_imu_link_0"/>
        <!-- putting it at the same z-level as the stereo -->
        <origin xyz="-0.0475 0.035 0.0" rpy="0 0 0"/>
    </joint>
    <link name="l_clav_0">
        <inertial>
            <mass value="4.466"/>
            <origin rpy="0 0 0" xyz="0 0 -0.084"/>
            <inertia ixx="0.011" ixy="0" ixz="0" iyy="0.009" iyz="0.004" izz="0.004"/>
        </inertial>
        <visual>
            <geometry>
                <mesh filename="r_clav.stl"/>
            </geometry>
        </visual>
        <collision>
            <origin rpy="1.05 0 0" xyz="0.004 -0.064 -0.247"/>
            <geometry>
                <box size="0.1 0.07 0.072"/>
            </geometry>
        </collision>
    </link>
    <link name="l_foot_0">
        <inertial>
            <mass value="2.410"/>
            <origin rpy="0 0 0" xyz="0.027 0 -0.067"/>
            <inertia ixx="0.002" ixy="0" ixz="0" iyy="0.007" iyz="0" izz="0.008"/>
        </inertial>
        <visual>
            <geometry>
                <mesh filename="l_foot.stl"/>
            </geometry>
        </visual>
        <collision>
            <origin rpy="0 0 0" xyz="0.023 0 -0.049119"/>
            <geometry>
                <!--<box size="0.227 0.133887 0.05"/>-->
                <box size="0.5 0.2 0.05"/>
            </geometry>
        </collision>
        <!--<collision>-->
            <!--<origin rpy="0 0 0" xyz="0.1225 0 -0.0641"/>-->
            <!--<geometry>-->
                <!--<box size="0.1 0.08 0.02"/>-->
            <!--</geometry>-->
        <!--</collision>-->
    </link>
    <link name="l_hand_0">
        <inertial>
            <mass value="0.5839"/>
            <origin rpy="0 0 0" xyz="0.00016 -0.08159 0.00002"/>
            <inertia ixx="0.000388" ixy="0" ixz="0" iyy="0.000477" iyz="0" izz="0.000379"/>
        </inertial>
    </link>
    <link name="l_larm_0">
        <inertial>
            <mass value="3.248"/>
            <origin rpy="0 0 0" xyz="0 0 0"/>
            <inertia ixx="0.00265" ixy="0" ixz="0" iyy="0.00446" iyz="0" izz="0.00446"/>
        </inertial>
        <visual>
            <geometry>
                <mesh filename="r_larm.stl"/>
            </geometry>
        </visual>
        <collision>
            <origin rpy="-1.5707963267949 0 0" xyz="0.00 -0.075 -0.01"/>
            <geometry>
                <cylinder length="0.04" radius="0.051"/>
            </geometry>
        </collision>
        <collision>
            <origin rpy="0 1.5707963267949 0" xyz="-0.012 0 0.0025"/>
            <geometry>
                <cylinder length="0.147" radius="0.045"/>
            </geometry>
        </collision>
        <collision>
            <origin rpy="0 0 0" xyz="-0.07 -0.077 -0.015"/>
            <geometry>
                <box size="0.025 0.155 0.07"/>
            </geometry>
        </collision>
        <collision>
            <origin rpy="0 0 0" xyz="0.05 -0.067 -0.009"/>
            <geometry>
                <box size="0.025 0.06 0.06"/>
            </geometry>
        </collision>
        <collision>
            <origin rpy="0 0 0" xyz="-0.032 -0.071 -0.06"/>
            <geometry>
                <box size="0.04 0.115 0.05"/>
            </geometry>
        </collision>
        <collision>
            <origin rpy="0 0 0" xyz="0.03 0.01 -0.05"/>
            <geometry>
                <box size="0.045 0.055 0.023"/>
            </geometry>
        </collision>
    </link>
    <link name="l_lfarm_0">
        <inertial>
            <mass value="0.648"/>
            <origin rpy="0 0 0" xyz="0.00017 -0.02515 0.00163"/>
            <inertia ixx="0.000764" ixy="0" ixz="0" iyy="0.000429" iyz="0" izz="0.000825"/>
        </inertial>
        <visual>
            <origin rpy="0 3.14159265359 0" xyz="0 0 0"/>
            <geometry>
                <mesh filename="r_hand.stl"/>
            </geometry>
        </visual>
        <collision>
            <origin rpy="1.5707963267949 0 0" xyz="0.00 -0.104 0.00"/>
            <geometry>
                <cylinder length="0.02" radius="0.031"/>
            </geometry>
        </collision>
        <collision>
            <origin rpy="1.5707963267949 0 0" xyz="0.00 -0.087 0.00"/>
            <geometry>
                <cylinder length="0.015" radius="0.045"/>
            </geometry>
        </collision>
        <collision>
            <origin rpy="1.5707963267949 0 0" xyz="0.00 -0.075 0.00"/>
            <geometry>
                <cylinder length="0.015" radius="0.052"/>
            </geometry>
        </collision>
        <collision>
            <origin rpy="1.5707963267949 0 0" xyz="0.00 -0.052 0.00"/>
            <geometry>
                <cylinder length="0.027" radius="0.043"/>
            </geometry>
        </collision>
    </link>
    <link name="l_lglut_0">
        <inertial>
            <mass value="0.898"/>
            <origin rpy="0 0 0" xyz="0.0133341 0.0170484 -0.0312052"/>
            <inertia ixx="0.000691326" ixy="-2.24344e-05" ixz="2.50508e-06" iyy="0.00126856" iyz="0.000137862" izz="0.00106487"/>
        </inertial>
        <visual>
            <geometry>
                <mesh filename="l_lglut.stl"/>
            </geometry>
        </visual>
        <collision>
            <origin rpy="1.5707963267949 0 0" xyz="0.05 0.027488 -0.067"/>
            <geometry>
                <cylinder length="0.060306" radius="0.02009687"/>
            </geometry>
        </collision>
        <collision>
            <origin rpy="0 1.5707963267949 0" xyz="0.0115 0 0"/>
            <geometry>
                <cylinder length="0.144" radius="0.02"/>
            </geometry>
        </collision>
    </link>
    <link name="l_lleg_0">
        <inertial>
            <mass value="4.515"/>
            <origin rpy="0 0 0" xyz="0.001 0 -0.187"/>
            <inertia ixx="0.077" ixy="0" ixz="-0.003" iyy="0.076" iyz="0" izz="0.01"/>
        </inertial>
        <visual>
            <geometry>
                <mesh filename="l_lleg.stl"/>
            </geometry>
        </visual>
        <collision>
            <origin rpy="0 0.10 0" xyz="0.02 0.00295 -0.182"/>
            <geometry>
                <cylinder length="0.40" radius="0.07"/>
            </geometry>
        </collision>
    </link>
    <link name="l_scap_0">
        <inertial>
            <mass value="3.899"/>
            <origin rpy="0 0 0" xyz="0 0 0"/>
            <inertia ixx="0.00319" ixy="0" ixz="0" iyy="0.00583" iyz="0" izz="0.00583"/>
        </inertial>
        <visual>
            <geometry>
                <mesh filename="r_scap.stl"/>
            </geometry>
        </visual>
        <collision>
            <origin rpy="1.5707963267949 0 0" xyz="-0.005 -0.115 -0.014"/>
            <geometry>
                <cylinder length="0.105" radius="0.057"/>
            </geometry>
        </collision>
        <collision>
            <origin rpy="0 0 0" xyz="-0.005 -0.075 -0.015"/>
            <geometry>
                <box size="0.16 0.17 0.08"/>
            </geometry>
        </collision>
        <collision>
            <origin rpy="2.25 0 0" xyz="0.076 -0.0615 0.0128"/>
            <geometry>
                <box size="0.02 0.029 0.018"/>
            </geometry>
        </collision>
        <collision>
            <origin rpy="1 0 0" xyz="-0.075 0.015 0.019"/>
            <geometry>
                <box size="0.028 0.090 0.05"/>
            </geometry>
        </collision>
    </link>
    <link name="l_talus_0">
        <inertial>
            <mass value="0.125"/>
            <origin rpy="0 0 0" xyz="0 0 0"/>
            <inertia ixx="1.01674e-05" ixy="0" ixz="0" iyy="8.42775e-06" iyz="0" izz="1.30101e-05"/>
        </inertial>
        <visual>
            <geometry>
                <mesh filename="l_talus.stl"/>
            </geometry>
        </visual>
        <collision>
            <origin rpy="0 1.5707963267949 0" xyz="0 0 0"/>
            <geometry>
                <cylinder length="0.029542" radius="0.010181"/>
            </geometry>
        </collision>
        <collision>
            <origin rpy="1.5707963267949 0 0" xyz="0 0 0"/>
            <geometry>
                <cylinder length="0.010059" radius="0.010348"/>
            </geometry>
        </collision>
    </link>
    <link name="l_uarm_0">
        <inertial>
            <mass value="4.386"/>
            <origin rpy="0 0 0" xyz="0 0.065 0"/>
            <inertia ixx="0.00656" ixy="0" ixz="0" iyy="0.00358" iyz="0" izz="0.00656"/>
        </inertial>
        <visual>
            <geometry>
                <mesh filename="r_uarm.stl"/>
            </geometry>
        </visual>
        <collision>
            <origin rpy="1.5708 0 0" xyz="0.0 -0.035 -0.005"/>
            <geometry>
                <cylinder length="0.11" radius="0.065"/>
            </geometry>
        </collision>
        <collision>
            <origin rpy="0 1.5707963267949 0" xyz="-0.01 -0.043 0.002"/>
            <geometry>
                <box size="0.05 0.07 0.15"/>
            </geometry>
        </collision>
    </link>
    <link name="l_ufarm_0">
        <inertial>
            <mass value="2.4798"/>
            <origin rpy="0 0 0" xyz="0.00015 0.08296 0.00037"/>
            <inertia ixx="0.012731" ixy="0" ixz="0" iyy="0.002857" iyz="0" izz="0.011948"/>
        </inertial>
        <visual>
            <geometry>
                <mesh filename="r_farm.stl"/>
            </geometry>
        </visual>
        <collision>
            <origin rpy="1.57 0 0" xyz="0 0.15 0"/>
            <geometry>
                <cylinder length="0.1" radius="0.053"/>
            </geometry>
        </collision>
        <collision>
            <origin rpy="0 1.5707963267949 0" xyz="-0.001 0.07 0.0"/>
            <geometry>
                <box size="0.08 0.09 0.11"/>
            </geometry>
        </collision>
        <collision>
            <origin rpy="0 1.57 0" xyz="0 0.005 0"/>
            <geometry>
                <cylinder length="0.125" radius="0.040"/>
            </geometry>
        </collision>
    </link>
    <link name="l_uglut_0">
        <inertial>
            <mass value="1.959"/>
            <origin rpy="0 0 0" xyz="0.00529262 -0.00344732 0.00313046"/>
            <inertia ixx="0.00074276" ixy="-3.79607e-08" ixz="-2.79549e-05" iyy="0.000688179" iyz="-3.2735e-08" izz="0.00041242"/>
        </inertial>
        <visual>
            <geometry>
                <mesh filename="l_uglut.stl"/>
            </geometry>
        </visual>
        <collision>
            <origin rpy="0 0 0" xyz="0 0 0"/>
            <geometry>
                <cylinder length="0.080842" radius="0.019841"/>
            </geometry>
        </collision>
    </link>
    <link name="l_uleg_0">
        <inertial>
            <mass value="8.204"/>
            <origin rpy="0 0 0" xyz="0 0 -0.21"/>
            <inertia ixx="0.09" ixy="0" ixz="0" iyy="0.09" iyz="0" izz="0.02"/>
        </inertial>
        <visual>
            <geometry>
                <mesh filename="l_uleg.stl"/>
            </geometry>
        </visual>
        <collision>
            <origin rpy="0 0 0" xyz="-0.0199 0.00585 -0.122"/>
            <geometry>
                <cylinder length="0.15" radius="0.09"/>
            </geometry>
        </collision>
        <collision>
            <origin rpy="0 -0.3 0" xyz="-0.032 -0.005 -0.224"/>
            <geometry>
                <cylinder length="0.15" radius="0.07"/>
            </geometry>
        </collision>
        <!-- to cover the logo shield -->
        <collision>
            <origin rpy="-0.15 0.13 0" xyz="0.003 0.015 -0.254"/>
            <geometry>
                <cylinder length="0.15" radius="0.05"/>
            </geometry>
        </collision>
        <!-- inside strut -->
        <collision>
            <origin rpy="0.0 0.0 0" xyz="-0.007 -0.053 -0.052"/>
            <geometry>
                <box size="0.07 0.038 0.15"/>
            </geometry>
        </collision>
        <!-- outside strut -->
        <collision>
            <origin rpy="0.0 0.0 0" xyz="-0.017 0.0595 -0.049"/>
            <geometry>
                <box size="0.07 0.038 0.14"/>
            </geometry>
        </collision>
    </link>
    <link name="ltorso_0">
        <inertial>
            <mass value="2.270"/>
            <origin rpy="0 0 0" xyz="-0.0112984 -3.15366e-06 0.0746835"/>
            <inertia ixx="0.0039092" ixy="-5.04491e-08" ixz="-0.000342157" iyy="0.00341694" iyz="4.87119e-07" izz="0.00174492"/>
        </inertial>
        <visual>
            <geometry>
                <mesh filename="ltorso.stl"/>
            </geometry>
        </visual>
    </link>
    <link name="mtorso_0">
        <inertial>
            <mass value="0.799"/>
            <origin rpy="0 0 0" xyz="-0.00816266 -0.0131245 0.0305974"/>
            <inertia ixx="0.000454181" ixy="-6.10764e-05" ixz="3.94009e-05" iyy="0.000483282" iyz="5.27463e-05" izz="0.000444215"/>
        </inertial>
        <visual>
            <geometry>
                <mesh filename="mtorso.stl"/>
            </geometry>
        </visual>
    </link>
    <link name="pelvis_0">
        <inertial>
            <mass value="9.509"/>
            <origin rpy="0 0 0" xyz="0.0111 0 0.0271"/>
            <inertia ixx="0.1244" ixy="0.0008" ixz="-0.0007" iyy="0.0958" iyz="-0.0005" izz="0.1167"/>
        </inertial>
        <visual>
            <geometry>
                <mesh filename="pelvis.stl"/>
            </geometry>
        </visual>
        <collision>
            <origin rpy="0 0 0" xyz="0.01 0.042 0.09"/>
            <geometry>
                <cylinder length="0.05" radius="0.16"/>
            </geometry>
        </collision>
        <collision>
            <origin rpy="0 0 0" xyz="0.01 -0.042 0.09"/>
            <geometry>
                <cylinder length="0.05" radius="0.16"/>
            </geometry>
        </collision>
    </link>
    <link name="r_clav_0">
        <inertial>
            <mass value="4.466"/>
            <origin rpy="0 0 0" xyz="0 0 -0.084"/>
            <inertia ixx="0.011" ixy="0" ixz="0" iyy="0.009" iyz="0.004" izz="0.004"/>
        </inertial>
        <visual>
            <geometry>
                <mesh filename="r_clav.stl"/>
            </geometry>
        </visual>
        <collision>
            <origin rpy="0 1.5707963267949 0" xyz="0 -0.11 -0.248"/>
            <geometry>
                <cylinder length="0.1525" radius="0.0555"/>
            </geometry>
        </collision>
        <collision>
            <origin rpy="0 0 0" xyz="0.005 -0.015 -0.08"/>
            <geometry>
                <cylinder length="0.26" radius="0.067"/>
            </geometry>
        </collision>
        <collision>
            <origin rpy="1.05 0 0" xyz="0.004 -0.064 -0.247"/>
            <geometry>
                <box size="0.1 0.07 0.072"/>
            </geometry>
        </collision>
    </link>
    <link name="r_foot_0">
        <inertial>
            <mass value="2.41"/>
            <origin rpy="0 0 0" xyz="0.027 0 -0.067"/>
            <inertia ixx="0.002" ixy="0" ixz="0" iyy="0.007" iyz="0" izz="0.008"/>
        </inertial>
        <visual>
            <geometry>
                <mesh filename="r_foot.stl"/>
            </geometry>
        </visual>
        <collision>
            <origin rpy="0 0 0" xyz="0.023 0 -0.049119"/>
            <geometry>
                <!--<box size="0.227 0.133887 0.05"/>-->
                <box size="0.5 0.2 0.05"/>
            </geometry>
        </collision>
        <!--<collision>-->
            <!--<origin rpy="0 0 0" xyz="0.1225 0 -0.0641"/>-->
            <!--<geometry>-->
                <!--<box size="0.1 0.08 0.02"/>-->
            <!--</geometry>-->
        <!--</collision>-->
    </link>
    <link name="r_hand_0">
        <inertial>
            <mass value="0.5839"/>
            <origin rpy="0 0 0" xyz="0.00016 -0.08159 0.00002"/>
            <inertia ixx="0.000388" ixy="0" ixz="0" iyy="0.000477" iyz="0" izz="0.000379"/>
        </inertial>
    </link>
    <link name="r_larm_0">
        <inertial>
            <mass value="3.248"/>
            <origin rpy="0 0 0" xyz="0 0 0"/>
            <inertia ixx="0.00265" ixy="0" ixz="0" iyy="0.00446" iyz="0" izz="0.00446"/>
        </inertial>
        <visual>
            <geometry>
                <mesh filename="r_larm.stl"/>
            </geometry>
        </visual>
        <collision>
            <origin rpy="-1.5707963267949 0 0" xyz="0.00 -0.075 -0.01"/>
            <geometry>
                <cylinder length="0.04" radius="0.051"/>
            </geometry>
        </collision>
        <collision>
            <origin rpy="0 1.5707963267949 0" xyz="-0.012 0 0.0025"/>
            <geometry>
                <cylinder length="0.147" radius="0.045"/>
            </geometry>
        </collision>
        <collision>
            <origin rpy="0 0 0" xyz="-0.07 -0.077 -0.015"/>
            <geometry>
                <box size="0.025 0.155 0.07"/>
            </geometry>
        </collision>
        <collision>
            <origin rpy="0 0 0" xyz="0.05 -0.067 -0.009"/>
            <geometry>
                <box size="0.025 0.06 0.06"/>
            </geometry>
        </collision>
        <collision>
            <origin rpy="0 0 0" xyz="-0.032 -0.071 -0.06"/>
            <geometry>
                <box size="0.04 0.115 0.05"/>
            </geometry>
        </collision>
        <collision>
            <origin rpy="0 0 0" xyz="0.03 0.01 -0.05"/>
            <geometry>
                <box size="0.045 0.055 0.023"/>
            </geometry>
        </collision>
    </link>
    <link name="r_lfarm_0">
        <inertial>
            <mass value="0.648"/>
            <origin rpy="0 0 0" xyz="0.00017 -0.02515 0.00163"/>
            <inertia ixx="0.000764" ixy="0" ixz="0" iyy="0.000429" iyz="0" izz="0.000825"/>
        </inertial>
        <visual>
            <origin rpy="0 3.14159265359 0" xyz="0 0 0"/>
            <geometry>
                <mesh filename="r_hand.stl"/>
            </geometry>
        </visual>
        <collision>
            <origin rpy="1.5707963267949 0 0" xyz="0.00 -0.104 0.00"/>
            <geometry>
                <cylinder length="0.02" radius="0.031"/>
            </geometry>
        </collision>
        <collision>
            <origin rpy="1.5707963267949 0 0" xyz="0.00 -0.087 0.00"/>
            <geometry>
                <cylinder length="0.015" radius="0.045"/>
            </geometry>
        </collision>
        <collision>
            <origin rpy="1.5707963267949 0 0" xyz="0.00 -0.075 0.00"/>
            <geometry>
                <cylinder length="0.015" radius="0.052"/>
            </geometry>
        </collision>
        <collision>
            <origin rpy="1.5707963267949 0 0" xyz="0.00 -0.052 0.00"/>
            <geometry>
                <cylinder length="0.027" radius="0.043"/>
            </geometry>
        </collision>
    </link>
    <link name="r_lglut_0">
        <inertial>
            <mass value="0.898"/>
            <origin rpy="0 0 0" xyz="0.0133341 -0.0170484 -0.0312052"/>
            <inertia ixx="0.000691326" ixy="2.24344e-05" ixz="2.50508e-06" iyy="0.00126856" iyz="-0.000137862" izz="0.00106487"/>
        </inertial>
        <visual>
            <geometry>
                <mesh filename="r_lglut.stl"/>
            </geometry>
        </visual>
        <collision>
            <origin rpy="1.5707963267949 0 0" xyz="0.05 -0.027488 -0.067"/>
            <geometry>
                <cylinder length="0.060306" radius="0.02009687"/>
            </geometry>
        </collision>
        <collision>
            <origin rpy="0 1.5707963267949 0" xyz="0.0105 0 0"/>
            <geometry>
                <cylinder length="0.142" radius="0.02"/>
            </geometry>
        </collision>
    </link>
    <link name="r_lleg_0">
        <inertial>
            <mass value="4.515"/>
            <origin rpy="0 0 0" xyz="0.001 0 -0.187"/>
            <inertia ixx="0.077" ixy="-0" ixz="-0.003" iyy="0.076" iyz="-0" izz="0.01"/>
        </inertial>
        <visual>
            <geometry>
                <mesh filename="r_lleg.stl"/>
            </geometry>
        </visual>
        <collision>
            <origin rpy="0 0.10 0" xyz="0.02 -0.00295 -0.182"/>
            <geometry>
                <cylinder length="0.40" radius="0.07"/>
            </geometry>
        </collision>
    </link>
    <link name="r_scap_0">
        <inertial>
            <mass value="3.899"/>
            <origin rpy="0 0 0" xyz="0 0 0"/>
            <inertia ixx="0.00319" ixy="0" ixz="0" iyy="0.00583" iyz="0" izz="0.00583"/>
        </inertial>
        <visual>
            <geometry>
                <mesh filename="r_scap.stl"/>
            </geometry>
        </visual>
        <collision>
            <origin rpy="1.5707963267949 0 0" xyz="-0.005 -0.115 -0.014"/>
            <geometry>
                <cylinder length="0.105" radius="0.057"/>
            </geometry>
        </collision>
        <collision>
            <origin rpy="0 0 0" xyz="-0.005 -0.075 -0.015"/>
            <geometry>
                <box size="0.16 0.17 0.08"/>
            </geometry>
        </collision>
        <collision>
            <origin rpy="2.25 0 0" xyz="0.076 -0.0615 0.0128"/>
            <geometry>
                <box size="0.02 0.029 0.018"/>
            </geometry>
        </collision>
        <collision>
            <origin rpy="1 0 0" xyz="-0.075 0.015 0.019"/>
            <geometry>
                <box size="0.028 0.090 0.05"/>
            </geometry>
        </collision>
    </link>
    <link name="r_talus_0">
        <inertial>
            <mass value="0.125"/>
            <origin rpy="0 0 0" xyz="0 0 0"/>
            <inertia ixx="1.01674e-05" ixy="0" ixz="0" iyy="8.42775e-06" iyz="0" izz="1.30101e-05"/>
        </inertial>
        <visual>
            <geometry>
                <mesh filename="r_talus.stl"/>
            </geometry>
        </visual>
        <collision>
            <origin rpy="0 1.5707963267949 0" xyz="0 0 0"/>
            <geometry>
                <cylinder length="0.029542" radius="0.010181"/>
            </geometry>
        </collision>
        <collision>
            <origin rpy="1.5707963267949 0 0" xyz="0 0 0"/>
            <geometry>
                <cylinder length="0.010059" radius="0.010348"/>
            </geometry>
        </collision>
    </link>
    <link name="r_uarm_0">
        <inertial>
            <mass value="4.386"/>
            <origin rpy="0 0 0" xyz="0 0.065 0"/>
            <inertia ixx="0.00656" ixy="0" ixz="0" iyy="0.00358" iyz="0" izz="0.00656"/>
        </inertial>
        <visual>
            <geometry>
                <mesh filename="r_uarm.stl"/>
            </geometry>
        </visual>
        <collision>
            <origin rpy="1.5708 0 0" xyz="0.0 -0.035 -0.005"/>
            <geometry>
                <cylinder length="0.11" radius="0.065"/>
            </geometry>
        </collision>
        <collision>
            <origin rpy="0 1.5707963267949 0" xyz="-0.01 -0.043 0.002"/>
            <geometry>
                <box size="0.05 0.07 0.15"/>
            </geometry>
        </collision>
    </link>
    <link name="r_ufarm_0">
        <inertial>
            <mass value="2.4798"/>
            <origin rpy="0 0 0" xyz="0.00015 0.08296 0.00037"/>
            <inertia ixx="0.012731" ixy="0" ixz="0" iyy="0.002857" iyz="0" izz="0.011948"/>
        </inertial>
        <visual>
            <geometry>
                <mesh filename="r_farm.stl"/>
            </geometry>
        </visual>
        <collision>
            <origin rpy="1.57 0 0" xyz="0 0.15 0"/>
            <geometry>
                <cylinder length="0.1" radius="0.053"/>
            </geometry>
        </collision>
        <collision>
            <origin rpy="0 1.57 0" xyz="0 0.005 0"/>
            <geometry>
                <cylinder length="0.125" radius="0.040"/>
            </geometry>
        </collision>
    </link>
    <link name="r_uglut_0">
        <inertial>
            <mass value="1.959"/>
            <origin rpy="0 0 0" xyz="0.00529262 0.00344732 0.00313046"/>
            <inertia ixx="0.00074276" ixy="3.79607e-08" ixz="-2.79549e-05" iyy="0.000688179" iyz="3.2735e-08" izz="0.00041242"/>
        </inertial>
        <visual>
            <geometry>
                <mesh filename="r_uglut.stl"/>
            </geometry>
        </visual>
        <collision>
            <origin rpy="0 0 0" xyz="0 0 0"/>
            <geometry>
                <cylinder length="0.080842" radius="0.019841"/>
            </geometry>
        </collision>
    </link>
    <link name="r_uleg_0">
        <inertial>
            <mass value="8.204"/>
            <origin rpy="0 0 0" xyz="0 0 -0.21"/>
            <inertia ixx="0.09" ixy="0" ixz="0" iyy="0.09" iyz="0" izz="0.02"/>
        </inertial>
        <visual>
            <geometry>
                <mesh filename="r_uleg.stl"/>
            </geometry>
        </visual>
        <collision>
            <origin rpy="0 0 0" xyz="-0.0199 -0.00585 -0.122"/>
            <geometry>
                <cylinder length="0.15" radius="0.09"/>
            </geometry>
        </collision>
        <collision>
            <origin rpy="0 -0.3 0" xyz="-0.032 0.005 -0.224"/>
            <geometry>
                <cylinder length="0.15" radius="0.07"/>
            </geometry>
        </collision>
        <!-- to cover the logo shield -->
        <collision>
            <origin rpy="0.15 0.13 0" xyz="0.003 -0.015 -0.254"/>
            <geometry>
                <cylinder length="0.15" radius="0.05"/>
            </geometry>
        </collision>
        <!-- inside strut -->
        <collision>
            <origin rpy="0.0 0.0 0" xyz="-0.007 0.053 -0.052"/>
            <geometry>
                <box size="0.07 0.038 0.15"/>
            </geometry>
        </collision>
        <!-- outside strut -->
        <collision>
            <origin rpy="0.0 0.0 0" xyz="-0.017 -0.0595 -0.049"/>
            <geometry>
                <box size="0.07 0.038 0.14"/>
            </geometry>
        </collision>
    </link>
    <link name="utorso_0">
        <inertial>
            <mass value="84.409"/>
            <origin rpy="0 0 0" xyz="-0.0622 0.0023 0.3157"/>
            <inertia ixx="1.577" ixy="-0.032" ixz="0.102" iyy="1.602" iyz="0.047" izz="0.565"/>
        </inertial>
        <visual>
            <geometry>
                <mesh filename="utorso.stl"/>
            </geometry>
        </visual>
        <collision>
            <origin rpy="0 0 0" xyz="-0.102 0 0.25"/>
            <geometry>
                <box size="0.4 0.35 0.5"/>
            </geometry>
        </collision>
        <collision>
            <origin rpy="0 1.5707 0" xyz="0.2 0 0.46"/>
            <geometry>
                <box size="0.13 0.50 0.10"/>
            </geometry>
        </collision>
        <collision>
            <origin rpy="0 1.7 0" xyz="0.2 0 0.285"/>
            <geometry>
                <box size="0.2 0.23 0.10"/>
            </geometry>
        </collision>
        <collision>
            <origin rpy="0 2.0 0" xyz="0.15 0 0.10"/>
            <geometry>
                <box size="0.2 0.18 0.10"/>
            </geometry>
        </collision>
        <collision>
            <origin rpy="0 0 0" xyz="-0.035 0 0.6265"/>
            <geometry>
                <box size="0.506306 0.341719 0.12"/>
            </geometry>
        </collision>
        <collision>
            <origin rpy="1.5707 0 0" xyz="0.208 0 0.8215"/>
            <geometry>
                <cylinder length="0.13" radius="0.008"/>
            </geometry>
        </collision>
        <collision>
            <origin rpy="-0.38535 0 0" xyz="0.208 -0.125 0.745"/>
            <geometry>
                <cylinder length="0.15" radius="0.008"/>
            </geometry>
        </collision>
        <collision>
            <origin rpy="0.38535 0 0" xyz="0.208 0.125 0.745"/>
            <geometry>
                <cylinder length="0.15" radius="0.008"/>
            </geometry>
        </collision>
        <collision>
            <origin rpy="-0.38535 0 0" xyz="0.063 -0.125 0.745"/>
            <geometry>
                <cylinder length="0.15" radius="0.008"/>
            </geometry>
        </collision>
        <collision>
            <origin rpy="0.38535 0 0" xyz="0.063 0.125 0.745"/>
            <geometry>
                <cylinder length="0.15" radius="0.008"/>
            </geometry>
        </collision>
        <collision>
            <origin rpy="1.5707 0 1.5707" xyz="0.14 0.06 0.8215"/>
            <geometry>
                <cylinder length="0.15" radius="0.008"/>
            </geometry>
        </collision>
        <collision>
            <origin rpy="1.5707 0 1.5707" xyz="0.14 -0.06 0.8215"/>
            <geometry>
                <cylinder length="0.15" radius="0.008"/>
            </geometry>
        </collision>
        <collision>
            <origin rpy="0 -0.65 0" xyz="-0.029 0 0.731"/>
            <geometry>
                <box size="0.2 0.25 0.01"/>
            </geometry>
        </collision>
        <collision>
            <origin rpy="1.5707 0 0" xyz="0.063 0 0.8215"/>
            <geometry>
                <cylinder length="0.13" radius="0.008"/>
            </geometry>
        </collision>
        <collision>
            <origin rpy="1.5707 0 0" xyz="0.261 0.156 0.6215"/>
            <geometry>
                <cylinder length="0.016" radius="0.055"/>
            </geometry>
        </collision>
        <collision>
            <origin rpy="1.5707 0 0" xyz="0.261 -0.156 0.6215"/>
            <geometry>
                <cylinder length="0.016" radius="0.055"/>
            </geometry>
        </collision>
    </link>
    <joint name="back_bkx_0" type="continuous">
        <origin rpy="0 0 0" xyz="0 0 0.05"/>
        <axis xyz="1 0 0"/>
        <parent link="mtorso_0"/>
        <child link="utorso_0"/>
        <dynamics damping="0.1" friction="0"/>
    </joint>
    <joint name="back_bky_0" type="continuous">
        <origin rpy="0 0 0" xyz="0 0 0.162"/>
        <axis xyz="0 1 0"/>
        <parent link="ltorso_0"/>
        <child link="mtorso_0"/>
        <dynamics damping="0.1" friction="0"/>
    </joint>
    <joint name="back_bkz_0" type="continuous">
        <origin rpy="0 0 0" xyz="-0.0125 0 0"/>
        <axis xyz="0 0 1"/>
        <parent link="pelvis_0"/>
        <child link="ltorso_0"/>
        <dynamics damping="0.1" friction="0"/>
    </joint>
    <joint name="l_arm_elx_0" type="continuous">
        <origin rpy="0 0 0" xyz="0 -0.119 0.0092"/>
        <axis xyz="-1.0 -0.0 -0.0"/>
        <parent link="l_uarm_0"/>
        <child link="l_larm_0"/>
        <dynamics damping="0.1" friction="0"/>
    </joint>
    <joint name="l_arm_ely_0" type="continuous">
        <origin rpy="0 0 0" xyz="0 -0.187 -0.016"/>
        <axis xyz="-0.0 -1.0 -0.0"/>
        <parent link="l_scap_0"/>
        <child link="l_uarm_0"/>
        <dynamics damping="0.1" friction="0"/>
    </joint>
    <joint name="l_arm_shx_0" type="continuous">
        <origin rpy="0 0 0" xyz="0 -0.11 -0.245"/>
        <axis xyz="-1.0 -0.0 -0.0"/>
        <parent link="l_clav_0"/>
        <child link="l_scap_0"/>
        <dynamics damping="0.1" friction="0"/>
    </joint>
    <joint name="l_arm_shz_0" type="continuous">
        <origin rpy="0 0 3.14159265359" xyz="0.1406 0.2256 0.4776"/>
        <axis xyz="0 0 1"/>
        <parent link="utorso_0"/>
        <child link="l_clav_0"/>
        <dynamics damping="0.1" friction="0"/>
    </joint>
    <joint name="l_arm_wrx_0" type="continuous">
        <origin rpy="0 0 0" xyz="0 0 0"/>
        <axis xyz="1 0 0"/>
        <parent link="l_ufarm_0"/>
        <child link="l_lfarm_0"/>
        <dynamics damping="0.1" friction="0"/>
    </joint>
    <joint name="l_arm_wry_0" type="continuous">
        <origin rpy="0 3.14159265359 0" xyz="0 -0.29955 -0.00921"/>
        <axis xyz="-0.0 -1.0 -0.0"/>
        <parent link="l_larm_0"/>
        <child link="l_ufarm_0"/>
        <dynamics damping="0.1" friction="0"/>
    </joint>
    <joint name="l_arm_wry2_0" type="continuous">
        <origin rpy="0 3.14159265359 0" xyz="0 0 0"/>
        <axis xyz="0 1 0"/>
        <parent link="l_lfarm_0"/>
        <child link="l_hand_0"/>
        <dynamics damping="0.1" friction="0"/>
    </joint>
    <joint name="l_leg_akx_0" type="continuous">
        <origin rpy="0 0 0" xyz="0 0 0"/>
        <axis xyz="1 0 0"/>
        <parent link="l_talus_0"/>
        <child link="l_foot_0"/>
        <dynamics damping="0.1" friction="0"/>
    </joint>
    <joint name="l_leg_aky_0" type="continuous">
        <origin rpy="0 0 0" xyz="0 0 -0.422"/>
        <axis xyz="0 1 0"/>
        <parent link="l_lleg_0"/>
        <child link="l_talus_0"/>
        <dynamics damping="0.1" friction="0"/>
    </joint>
    <joint name="l_leg_hpx_0" type="continuous">
        <origin rpy="0 0 0" xyz="0 0 0"/>
        <axis xyz="1 0 0"/>
        <parent link="l_uglut_0"/>
        <child link="l_lglut_0"/>
        <dynamics damping="0.1" friction="0"/>
    </joint>
    <joint name="l_leg_hpy_0" type="continuous">
        <origin rpy="0 0 0" xyz="0.05 0.0225 -0.066"/>
        <axis xyz="0 1 0"/>
        <parent link="l_lglut_0"/>
        <child link="l_uleg_0"/>
        <dynamics damping="0.1" friction="0"/>
    </joint>
    <joint name="l_leg_hpz_0" type="continuous">
        <origin rpy="0 0 0" xyz="0 0.089 0"/>
        <axis xyz="0 0 1"/>
        <parent link="pelvis_0"/>
        <child link="l_uglut_0"/>
        <dynamics damping="0.1" friction="0"/>
    </joint>
    <joint name="l_leg_kny_0" type="continuous">
        <origin rpy="0 0 0" xyz="-0.05 0 -0.374"/>
        <axis xyz="0 1 0"/>
        <parent link="l_uleg_0"/>
        <child link="l_lleg_0"/>
        <dynamics damping="0.1" friction="0"/>
    </joint>
    <joint name="neck_ry_0" type="fixed">
        <origin rpy="0 0 0" xyz="0.2546 0 0.6215"/>
        <axis xyz="0 1 0"/>
        <parent link="utorso_0"/>
        <child link="head_0"/>
        <dynamics damping="0.1" friction="0"/>
    </joint>
    <joint name="r_arm_elx_0" type="continuous">
        <origin rpy="0 0 0" xyz="0 -0.119 0.0092"/>
        <axis xyz="1 0 0"/>
        <parent link="r_uarm_0"/>
        <child link="r_larm_0"/>
        <dynamics damping="0.1" friction="0"/>
    </joint>
    <joint name="r_arm_ely_0" type="continuous">
        <origin rpy="0 0 0" xyz="0 -0.187 -0.016"/>
        <axis xyz="0 1 0"/>
        <parent link="r_scap_0"/>
        <child link="r_uarm_0"/>
        <dynamics damping="0.1" friction="0"/>
    </joint>
    <joint name="r_arm_shx_0" type="continuous">
        <origin rpy="0 0 0" xyz="0 -0.11 -0.245"/>
        <axis xyz="1 0 0"/>
        <parent link="r_clav_0"/>
        <child link="r_scap_0"/>
        <dynamics damping="0.1" friction="0"/>
    </joint>
    <joint name="r_arm_shz_0" type="continuous">
        <origin rpy="0 0 0" xyz="0.1406 -0.2256 0.4776"/>
        <axis xyz="0 0 1"/>
        <parent link="utorso_0"/>
        <child link="r_clav_0"/>
        <dynamics damping="0.1" friction="0"/>
    </joint>
    <joint name="r_arm_wrx_0" type="continuous">
        <origin rpy="0 0 0" xyz="0 0 0"/>
        <axis xyz="1 0 0"/>
        <parent link="r_ufarm_0"/>
        <child link="r_lfarm_0"/>
        <dynamics damping="0.1" friction="0"/>
    </joint>
    <joint name="r_arm_wry_0" type="continuous">
        <origin rpy="0 0 0" xyz="0 -0.29955 -0.00921"/>
        <axis xyz="0 1 0"/>
        <parent link="r_larm_0"/>
        <child link="r_ufarm_0"/>
        <dynamics damping="0.1" friction="0"/>
    </joint>
    <joint name="r_arm_wry2_0" type="continuous">
        <origin rpy="0 0 0" xyz="0 0 0"/>
        <axis xyz="0 1 0"/>
        <parent link="r_lfarm_0"/>
        <child link="r_hand_0"/>
        <dynamics damping="0.1" friction="0"/>
    </joint>
    <joint name="r_leg_akx_0" type="continuous">
        <origin rpy="0 0 0" xyz="0 0 0"/>
        <axis xyz="1 0 0"/>
        <parent link="r_talus_0"/>
        <child link="r_foot_0"/>
        <dynamics damping="0.1" friction="0"/>
    </joint>
    <joint name="r_leg_aky_0" type="continuous">
        <origin rpy="0 0 0" xyz="0 0 -0.422"/>
        <axis xyz="0 1 0"/>
        <parent link="r_lleg_0"/>
        <child link="r_talus_0"/>
        <dynamics damping="0.1" friction="0"/>
    </joint>
    <joint name="r_leg_hpx_0" type="continuous">
        <origin rpy="0 0 0" xyz="0 0 0"/>
        <axis xyz="1 0 0"/>
        <parent link="r_uglut_0"/>
        <child link="r_lglut_0"/>
        <dynamics damping="0.1" friction="0"/>
    </joint>
    <joint name="r_leg_hpy_0" type="continuous">
        <origin rpy="0 0 0" xyz="0.05 -0.0225 -0.066"/>
        <axis xyz="0 1 0"/>
        <parent link="r_lglut_0"/>
        <child link="r_uleg_0"/>
        <dynamics damping="0.1" friction="0"/>
    </joint>
    <joint name="r_leg_hpz_0" type="continuous">
        <origin rpy="0 0 0" xyz="0 -0.089 0"/>
        <axis xyz="0 0 1"/>
        <parent link="pelvis_0"/>
        <child link="r_uglut_0"/>
        <dynamics damping="0.1" friction="0"/>
    </joint>
    <joint name="r_leg_kny_0" type="continuous">
        <origin rpy="0 0 0" xyz="-0.05 0 -0.374"/>
        <axis xyz="0 1 0"/>
        <parent link="r_uleg_0"/>
        <child link="r_lleg_0"/>
        <dynamics damping="0.1" friction="0"/>
    </joint>
    <link name="r_situational_awareness_camera_link_0">
        <inertial>
            <mass value="0.1"/>
            <origin xyz="0 0 0"/>
            <inertia ixx="0.00001" ixy="0" ixz="0" iyy="0.00001" iyz="0" izz="0.00001"/>
        </inertial>
        <visual>
            <origin rpy="0 0 0" xyz="0 0 0"/>
            <geometry>
                <box size="0.01 0.01 0.01"/>
            </geometry>
        </visual>
    </link>
    <joint name="r_situational_awareness_camera_joint_0" type="fixed">
        <parent link="utorso_0"/>
        <child link="r_situational_awareness_camera_link_0"/>
        <!-- SA camera mounted above the multisense head -->
        <origin rpy="0 0 -1.309" xyz="0.155 -0.121 0.785"/>
    </joint>
    <joint name="r_situational_awareness_camera_optical_frame_joint_0" type="fixed">
        <origin rpy="-1.5708 0.0 -1.5708" xyz="0 0 0"/>
        <parent link="r_situational_awareness_camera_link_0"/>
        <child link="r_situational_awareness_camera_optical_frame_0"/>
    </joint>
    <link name="r_situational_awareness_camera_optical_frame_0"/>
    <link name="l_situational_awareness_camera_link_0">
        <inertial>
            <mass value="0.1"/>
            <origin xyz="0 0 0"/>
            <inertia ixx="0.00001" ixy="0" ixz="0" iyy="0.00001" iyz="0" izz="0.00001"/>
        </inertial>
        <visual>
            <origin rpy="0 0 0" xyz="0 0 0"/>
            <geometry>
                <box size="0.01 0.01 0.01"/>
            </geometry>
        </visual>
    </link>
    <joint name="l_situational_awareness_camera_joint_0" type="fixed">
        <parent link="utorso_0"/>
        <child link="l_situational_awareness_camera_link_0"/>
        <!-- SA camera mounted above the multisense head -->
        <origin rpy="0 0 1.309" xyz="0.155 0.121 0.785"/>
    </joint>
    <joint name="l_situational_awareness_camera_optical_frame_joint_0" type="fixed">
        <origin rpy="-1.5708 0.0 -1.5708" xyz="0 0 0"/>
        <parent link="l_situational_awareness_camera_link_0"/>
        <child link="l_situational_awareness_camera_optical_frame_0"/>
    </joint>
    <link name="l_situational_awareness_camera_optical_frame_0"/>
</robot>