<?xml version="1.0" ?>
<!-- =================================================================================== -->
<!-- |    This document was autogenerated by xacro from /home/dbellicoso/catkin_ws/src/anymal_beth/anymal_beth_description/urdf/anymal_beth.urdf.xacro | -->
<!-- |    EDITING THIS FILE BY HAND IS NOT RECOMMENDED                                 | -->
<!-- =================================================================================== -->
<!--Copyright (C) 2015 by Dario Bellicoso                                    -->
<!--bellicosodario@gmail.com                                                 -->
<!--                                                                         -->
<!--This program is free software; you can redistribute it and/or modify     -->
<!--it under the terms of the Lesser GNU General Public License as published -->
<!--by the Free Software Foundation; either version 3 of the License, or     -->
<!--(at your option) any later version.                                      -->
<!--                                                                         -->
<!--This program is distributed in the hope that it will be useful,          -->
<!--but WITHOUT ANY WARRANTY; without even the implied warranty of           -->
<!--MERCHANTABILITY or FITNESS FOR A PARTICULAR PURPOSE. See the             -->
<!--Lesser GNU General Public License for more details.                      -->
<!--                                                                         -->
<!--You should have received a copy of the Lesser GNU General Public License -->
<!--along with this program. If not, see <http://www.gnu.org/licenses/>.     -->
<!-- This file contains the description of the ANYmal Beth robot. -->
<robot name="singlebody" xmlns:xacro="http://www.ros.org/wiki/xacro">
    <!-- Xacro:Properties -->
    <!-- [m] -->
    <!-- Base link -->
    <link name="base">
        <visual>
            <origin rpy="0 0 0" xyz="0 0 0"/>
            <geometry>
                <box size="1 1 1"/>
            </geometry>
        </visual>
        <collision>
            <!-- Main Body -->
            <origin rpy="0 0 0" xyz="0 0 0"/>
            <geometry>
                <box size="1 1 1"/>
            </geometry>
        </collision>
        <inertial>
            <origin rpy="0 0 0" xyz="0 0 0"/>
            <mass value="10"/>
            <inertia ixx="0.4167" ixy="0" ixz="0" iyy="0.4167" iyz="0" izz="0.4167"/>
        </inertial>
    </link>
	<joint name="revolute" type="revolute">
        <parent link="base"/>
        <child link="bar"/>
        <origin xyz="0.0 0.0 0.7"/>
        <axis xyz="0 0 1"/>
        <limit effort="80" lower="-6.28" upper="6.28" velocity="15"/>
        <dynamics damping="0.0" friction="0.0"/>
    </joint>
    <link name="bar">
		<visual>
			<origin rpy="0 0 0" xyz="0 0 0"/>
			<geometry>
				<box size="1 0.2 0.2"/>
			</geometry>
		</visual>
		<collision>
			<!-- Main Body -->
			<origin rpy="0 0 0" xyz="0 0 0"/>
			<geometry>
				<box size="1 0.2 0.2"/>
			</geometry>
		</collision>
		<inertial>
			<origin rpy="0 0 0" xyz="0 0 0"/>
			<mass value="10"/>
			<inertia ixx="0.4167" ixy="0" ixz="0" iyy="0.4167" iyz="0" izz="0.4167"/>
		</inertial>
	</link>
</robot>