    <link name="base_%d">
        <collision>
            <!-- Main Body -->
            <origin rpy="0 0 0" xyz="0 0 0.08"/>
            <geometry>
                <box size="0.531 0.232 0.26"/>
            </geometry>
        </collision>
        <inertial>
            <origin rpy="0 0 0" xyz="0.022 -0.01 0.01"/>
            <mass value="21.39"/>
            <inertia ixx="0.268388530624" ixy="0.000775392455422" ixz="-0.0151848534451" iyy="0.884235660795" iyz="-0.000989297489507" izz="0.829158678306"/>
        </inertial>
    </link>
    <!-- Fixed joint to add dummy inertia link -->
    <joint name="base_to_world_%d" type="floating">
        <parent link="world"/>
        <child link="base_%d"/>
        <origin rpy="0 0 0" xyz="%d %d %d"/>
    </joint>
    <!-- Xacro:Properties -->
    <!-- [m] -->
    <!-- [Nm] -->
    <link name="LF_HIP_%d">
        <collision>
            <origin rpy="1.57079632679 0 0" xyz="0.0585 0.0315 0.0"/>
            <geometry>
                <cylinder length="0.08" radius="0.04"/>
            </geometry>
        </collision>
        <inertial>
            <origin rpy="0 0 0" xyz="0.0542 -0.0136 0.0"/>
            <mass value="1.1064"/>
            <inertia ixx="0.00123301508523" ixy="-6.4285329973e-05" ixz="6.9990104e-08" iyy="0.000993231183395" iyz="2.327401345e-06" izz="0.00142160349098"/>
        </inertial>
    </link>
    <!-- Hip joint -->
    <joint name="LF_HAA_%d" type="revolute">
        <parent link="base_%d"/>
        <child link="LF_HIP_%d"/>
        <origin xyz="0.2629 0.115 0.0"/>
        <axis xyz="1 0 0"/>
        <limit effort="80" lower="-6.28" upper="6.28" velocity="15"/>
        <dynamics damping="0.0" friction="0.0"/>
    </joint>
    <!-- Xacro:Properties -->
    <!-- [m] -->
    <!-- [Nm] -->
    <link name="LF_THIGH_%d">
        <!--collision>
            <origin rpy="0.145 0 0" xyz="0 0.02 -0.1"/>
            <geometry>
                <cylinder length="0.2" radius="0.01"/>
            </geometry>
        </collision-->
        <collision>
            <origin rpy="1.57079632679 0 0" xyz="0.0 0.07 -0.25"/>
            <geometry>
                <cylinder length="0.08" radius="0.04"/>
            </geometry>
        </collision>
        <inertial>
            <origin rpy="0 0 0" xyz="0.0008 0.0545 -0.1975"/>
            <mass value="1.51"/>
            <inertia ixx="0.0147571628275" ixy="-1.7996507882e-05" ixz="0.000205877679383" iyy="0.0144188925719" iyz="-0.00181291342366" izz="0.00178449075964"/>
        </inertial>
    </link>
    <!-- Thigh joint -->
    <joint name="LF_HFE_%d" type="revolute">
        <parent link="LF_HIP_%d"/>
        <child link="LF_THIGH_%d"/>
        <origin xyz="0.0585                    0.0315                    0.0"/>
        <axis xyz="0 1 0"/>
        <limit effort="80" lower="-6.28" upper="6.28" velocity="15"/>
        <dynamics damping="0.0" friction="0.0"/>
    </joint>
    <!-- Xacro:Properties -->
    <!-- [m] -->
    <!-- [Nm] -->
    <link name="LF_SHANK_%d">
        <collision>
            <origin rpy="-0.0 0.34 0" xyz="0.06 -0.03 -0.18"/>
            <geometry>
                <cylinder length="0.19" radius="0.015"/>
            </geometry>
        </collision>
        <inertial>
            <origin rpy="0 0 0" xyz="0.016355414056 -0.00562219106 -0.064350437219"/>
            <mass value="0.318"/>
            <inertia ixx="0.0037693717909" ixy="-7.7334500762e-05" ixz="-0.000152069372983" iyy="0.00400446467635" iyz="-0.0003218356083" izz="0.000418471691904"/>
        </inertial>
    </link>
    <!-- Shank joint -->
    <joint name="LF_KFE_%d" type="revolute">
        <parent link="LF_THIGH_%d"/>
        <child link="LF_SHANK_%d"/>
        <origin xyz="0.0 0.111 -0.25"/>
        <axis xyz="0 1 0"/>
        <limit effort="80" lower="-6.28" upper="6.28" velocity="15"/>
        <dynamics damping="0.0" friction="0.0"/>
    </joint>
    <!-- Foot mount link -->
    <link name="LF_FOOT_MOUNT_%d"/>
    <!-- Foot mount joint / ankle -->
    <joint name="LF_ANKLE_JOINT_%d" type="fixed">
        <parent link="LF_SHANK_%d"/>
        <child link="LF_FOOT_MOUNT_%d"/>
        <origin rpy="0.323 0.549 0" xyz="0.0 -0.016 -0.31"/>
    </joint>
    <!-- Xacro:Properties -->
    <!-- [m] -->
    <link name="LF_FOOT_SENSOR_%d">
        <collision>
            <origin rpy="0 0 0" xyz="0.0 0.0 0"/>
            <geometry>
                <sphere radius="0.03"/>
            </geometry>
        </collision>
        <inertial>
            <origin rpy="0 0 0" xyz="-5.552058e-06 7.1133124e-05 -0.021388647779"/>
            <mass value="0.1922685"/>
            <inertia ixx="8.3086410294e-05" ixy="4.16901601e-07" ixz="3.99054799e-07" iyy="8.2860209667e-05" iyz="-3.45712252e-07" izz="8.1948124086e-05"/>
        </inertial>
    </link>
    <!-- Foot sensor joint -->
    <joint name="LF_MOUNT_TO_SENSOR_%d" type="fixed">
        <parent link="LF_FOOT_MOUNT_%d"/>
        <child link="LF_FOOT_SENSOR_%d"/>
        <origin rpy="0 0 0" xyz="0 0 0"/>
    </joint>
    <!-- Gazebo customization -->
    <gazebo reference="LF_FOOT_SENSOR">
        <kp>1000000.0</kp>
        <kd>100.0</kd>
        <mu1>0.8</mu1>
        <mu2>0.8</mu2>
    </gazebo>
    <gazebo reference="LF_MOUNT_TO_SENSOR"/>
    <!-- Foot link -->
    <link name="LF_FOOT_%d">
    </link>
    <!-- Foot joint -->
    <joint name="LF_SENSOR_TO_FOOT_%d" type="fixed">
        <parent link="LF_FOOT_SENSOR_%d"/>
        <child link="LF_FOOT_%d"/>
        <origin rpy="0 0 0" xyz="0.0 0.0 -0.0385"/>
    </joint>
    <!-- Xacro:Properties -->
    <!-- [m] -->
    <!-- [Nm] -->
    <link name="RF_HIP_%d">
        <collision>
            <origin rpy="1.57079632679 0 0" xyz="0.0585 -0.0315 0.0"/>
            <geometry>
                <cylinder length="0.08" radius="0.04"/>
            </geometry>
        </collision>
        <inertial>
            <origin rpy="0 0 0" xyz="0.0542 0.0136 0.0"/>
            <mass value="1.1064"/>
            <inertia ixx="0.00123301508523" ixy="6.4285329973e-05" ixz="6.9990104e-08" iyy="0.000993231183395" iyz="-2.327401345e-06" izz="0.00142160349098"/>
        </inertial>
    </link>
    <!-- Hip joint -->
    <joint name="RF_HAA_%d" type="revolute">
        <parent link="base_%d"/>
        <child link="RF_HIP_%d"/>
        <origin xyz="0.2629 -0.115 0.0"/>
        <axis xyz="1 0 0"/>
        <limit effort="80" lower="-6.28" upper="6.28" velocity="15"/>
        <dynamics damping="0.0" friction="0.0"/>
    </joint>
    <!-- Xacro:Properties -->
    <!-- [m] -->
    <!-- [Nm] -->
    <link name="RF_THIGH_%d">
        <!--collision>
            <origin rpy="-0.145 0 0" xyz="0 -0.02 -0.1"/>
            <geometry>
                <cylinder length="0.2" radius="0.01"/>
            </geometry>
        </collision-->
        <collision>
            <origin rpy="1.57079632679 0 0" xyz="0.0 -0.07 -0.25"/>
            <geometry>
                <cylinder length="0.08" radius="0.04"/>
            </geometry>
        </collision>
        <inertial>
            <origin rpy="0 0 0" xyz="0.0008 -0.0545 -0.1975"/>
            <mass value="1.51"/>
            <inertia ixx="0.0147571628275" ixy="1.7996507882e-05" ixz="0.000205877679383" iyy="0.0144188925719" iyz="0.00181291342366" izz="0.00178449075964"/>
        </inertial>
    </link>
    <!-- Thigh joint -->
    <joint name="RF_HFE_%d" type="revolute">
        <parent link="RF_HIP_%d"/>
        <child link="RF_THIGH_%d"/>
        <origin xyz="0.0585                    -0.0315                    0.0"/>
        <axis xyz="0 1 0"/>
        <limit effort="80" lower="-6.28" upper="6.28" velocity="15"/>
        <dynamics damping="0.0" friction="0.0"/>
    </joint>
    <!-- Xacro:Properties -->
    <!-- [m] -->
    <!-- [Nm] -->
    <link name="RF_SHANK_%d">
        <collision>
            <origin rpy="0.0 0.34 0" xyz="0.06 0.03 -0.18"/>
            <geometry>
                <cylinder length="0.19" radius="0.015"/>
            </geometry>
        </collision>
        <inertial>
            <origin rpy="0 0 0" xyz="0.016355414056 0.00562219106 -0.064350437219"/>
            <mass value="0.318"/>
            <inertia ixx="0.0037693717909" ixy="7.7334500762e-05" ixz="-0.000152069372983" iyy="0.00400446467635" iyz="0.0003218356083" izz="0.000418471691904"/>
        </inertial>
    </link>
    <!-- Shank joint -->
    <joint name="RF_KFE_%d" type="revolute">
        <parent link="RF_THIGH_%d"/>
        <child link="RF_SHANK_%d"/>
        <origin xyz="0.0 -0.111 -0.25"/>
        <axis xyz="0 1 0"/>
        <limit effort="80" lower="-6.28" upper="6.28" velocity="15"/>
        <dynamics damping="0.0" friction="0.0"/>
    </joint>
    <!-- Foot mount link -->
    <link name="RF_FOOT_MOUNT_%d"/>
    <!-- Foot mount joint / ankle -->
    <joint name="RF_ANKLE_JOINT_%d" type="fixed">
        <parent link="RF_SHANK_%d"/>
        <child link="RF_FOOT_MOUNT_%d"/>
        <origin rpy="-0.323 0.549 0" xyz="0.0 0.016 -0.31"/>
    </joint>
    <!-- Xacro:Properties -->
    <!-- [m] -->
    <link name="RF_FOOT_SENSOR_%d">
        <collision>
            <origin rpy="0 0 0" xyz="0.0 0.0 0"/>
            <geometry>
                <sphere radius="0.03"/>
            </geometry>
        </collision>
        <inertial>
            <origin rpy="0 0 0" xyz="-5.552058e-06 -7.1133124e-05 -0.021388647779"/>
            <mass value="0.1922685"/>
            <inertia ixx="8.3086410294e-05" ixy="-4.16901601e-07" ixz="3.99054799e-07" iyy="8.2860209667e-05" iyz="3.45712252e-07" izz="8.1948124086e-05"/>
        </inertial>
    </link>
    <!-- Foot sensor joint -->
    <joint name="RF_MOUNT_TO_SENSOR_%d" type="fixed">
        <parent link="RF_FOOT_MOUNT_%d"/>
        <child link="RF_FOOT_SENSOR_%d"/>
        <origin rpy="0 0 0" xyz="0 0 0"/>
    </joint>
    <!-- Gazebo customization -->
    <gazebo reference="RF_FOOT_SENSOR">
        <kp>1000000.0</kp>
        <kd>100.0</kd>
        <mu1>0.8</mu1>
        <mu2>0.8</mu2>
    </gazebo>
    <gazebo reference="RF_MOUNT_TO_SENSOR"/>
    <!-- Foot link -->
    <link name="RF_FOOT_%d">
    </link>
    <!-- Foot joint -->
    <joint name="RF_SENSOR_TO_FOOT_%d" type="fixed">
        <parent link="RF_FOOT_SENSOR_%d"/>
        <child link="RF_FOOT_%d"/>
        <origin rpy="0 0 0" xyz="0.0 0.0 -0.0385"/>
    </joint>
    <!-- Xacro:Properties -->
    <!-- [m] -->
    <!-- [Nm] -->
    <link name="LH_HIP_%d">
        <collision>
            <origin rpy="-1.57079632679 0 0" xyz="-0.0585 0.0315 0.0"/>
            <geometry>
                <cylinder length="0.08" radius="0.04"/>
            </geometry>
        </collision>
        <inertial>
            <origin rpy="0 0 0" xyz="-0.0542 -0.0136 0.0"/>
            <mass value="1.1064"/>
            <inertia ixx="0.00123301508523" ixy="6.4285329973e-05" ixz="-6.9990104e-08" iyy="0.000993231183395" iyz="2.327401345e-06" izz="0.00142160349098"/>
        </inertial>
    </link>
    <!-- Hip joint -->
    <joint name="LH_HAA_%d" type="revolute">
        <parent link="base_%d"/>
        <child link="LH_HIP_%d"/>
        <origin xyz="-0.2629 0.115 0.0"/>
        <axis xyz="1 0 0"/>
        <limit effort="80" lower="-6.28" upper="6.28" velocity="15"/>
        <dynamics damping="0.0" friction="0.0"/>
    </joint>
    <!-- Xacro:Properties -->
    <!-- [m] -->
    <!-- [Nm] -->
    <link name="LH_THIGH_%d">
        <collision>
            <origin rpy="1.57079632679 0 0" xyz="0.0 0.07 -0.25"/>
            <geometry>
                <cylinder length="0.08" radius="0.04"/>
            </geometry>
        </collision>
        <inertial>
            <origin rpy="0 0 0" xyz="-0.0008 0.0545 -0.1975"/>
            <mass value="1.51"/>
            <inertia ixx="0.0147571628275" ixy="1.7996507882e-05" ixz="-0.000205877679383" iyy="0.0144188925719" iyz="-0.00181291342366" izz="0.00178449075964"/>
        </inertial>
    </link>
    <!-- Thigh joint -->
    <joint name="LH_HFE_%d" type="revolute">
        <parent link="LH_HIP_%d"/>
        <child link="LH_THIGH_%d"/>
        <origin xyz="-0.0585                    0.0315                    0.0"/>
        <axis xyz="0 1 0"/>
        <limit effort="80" lower="-6.28" upper="6.28" velocity="15"/>
        <dynamics damping="0.0" friction="0.0"/>
    </joint>
    <!-- Xacro:Properties -->
    <!-- [m] -->
    <!-- [Nm] -->
    <link name="LH_SHANK_%d">
        <collision>
            <origin rpy="-0.0 -0.34 0" xyz="-0.06 -0.03 -0.18"/>
            <geometry>
                <cylinder length="0.19" radius="0.015"/>
            </geometry>
        </collision>
        <inertial>
            <origin rpy="0 0 0" xyz="-0.016355414056 -0.00562219106 -0.064350437219"/>
            <mass value="0.318"/>
            <inertia ixx="0.0037693717909" ixy="7.7334500762e-05" ixz="0.000152069372983" iyy="0.00400446467635" iyz="-0.0003218356083" izz="0.000418471691904"/>
        </inertial>
    </link>
    <!-- Shank joint -->
    <joint name="LH_KFE_%d" type="revolute">
        <parent link="LH_THIGH_%d"/>
        <child link="LH_SHANK_%d"/>
        <origin xyz="-0.0 0.111 -0.25"/>
        <axis xyz="0 1 0"/>
        <limit effort="80" lower="-6.28" upper="6.28" velocity="15"/>
        <dynamics damping="0.0" friction="0.0"/>
    </joint>
    <!-- Foot mount link -->
    <link name="LH_FOOT_MOUNT_%d"/>
    <!-- Foot mount joint / ankle -->
    <joint name="LH_ANKLE_JOINT_%d" type="fixed">
        <parent link="LH_SHANK_%d"/>
        <child link="LH_FOOT_MOUNT_%d"/>
        <origin rpy="0.323 -0.549 0" xyz="-0.0 -0.016 -0.31"/>
    </joint>
    <!-- Xacro:Properties -->
    <!-- [m] -->
    <link name="LH_FOOT_SENSOR_%d">
        <collision>
            <origin rpy="0 0 0" xyz="0.0 0.0 0"/>
            <geometry>
                <sphere radius="0.03"/>
            </geometry>
        </collision>
        <inertial>
            <origin rpy="0 0 0" xyz="5.552058e-06 7.1133124e-05 -0.021388647779"/>
            <mass value="0.1922685"/>
            <inertia ixx="8.3086410294e-05" ixy="-4.16901601e-07" ixz="-3.99054799e-07" iyy="8.2860209667e-05" iyz="-3.45712252e-07" izz="8.1948124086e-05"/>
        </inertial>
    </link>
    <!-- Foot sensor joint -->
    <joint name="LH_MOUNT_TO_SENSOR_%d" type="fixed">
        <parent link="LH_FOOT_MOUNT_%d"/>
        <child link="LH_FOOT_SENSOR_%d"/>
        <origin rpy="0 0 0" xyz="0 0 0"/>
    </joint>
    <!-- Gazebo customization -->
    <gazebo reference="LH_FOOT_SENSOR">
        <kp>1000000.0</kp>
        <kd>100.0</kd>
        <mu1>0.8</mu1>
        <mu2>0.8</mu2>
    </gazebo>
    <gazebo reference="LH_MOUNT_TO_SENSOR"/>
    <!-- Foot link -->
    <link name="LH_FOOT_%d">
    </link>
    <!-- Foot joint -->
    <joint name="LH_SENSOR_TO_FOOT_%d" type="fixed">
        <parent link="LH_FOOT_SENSOR_%d"/>
        <child link="LH_FOOT_%d"/>
        <origin rpy="0 0 0" xyz="0.0 0.0 -0.0385"/>
    </joint>
    <!-- Xacro:Properties -->
    <!-- [m] -->
    <!-- [Nm] -->
    <link name="RH_HIP_%d">
        <collision>
            <origin rpy="-1.57079632679 0 0" xyz="-0.0585 -0.0315 0.0"/>
            <geometry>
                <cylinder length="0.08" radius="0.04"/>
            </geometry>
        </collision>
        <inertial>
            <origin rpy="0 0 0" xyz="-0.0542 0.0136 0.0"/>
            <mass value="1.1064"/>
            <inertia ixx="0.00123301508523" ixy="-6.4285329973e-05" ixz="-6.9990104e-08" iyy="0.000993231183395" iyz="-2.327401345e-06" izz="0.00142160349098"/>
        </inertial>
    </link>
    <!-- Hip joint -->
    <joint name="RH_HAA_%d" type="revolute">
        <parent link="base_%d"/>
        <child link="RH_HIP_%d"/>
        <origin xyz="-0.2629 -0.115 0.0"/>
        <axis xyz="1 0 0"/>
        <limit effort="80" lower="-6.28" upper="6.28" velocity="15"/>
        <dynamics damping="0.0" friction="0.0"/>
    </joint>
    <!-- Xacro:Properties -->
    <!-- [m] -->
    <!-- [Nm] -->
    <link name="RH_THIGH_%d">
        <!--collision>
            <origin rpy="-0.145 0 0" xyz="0 -0.02 -0.1"/>
            <geometry>
                <cylinder length="0.2" radius="0.01"/>
            </geometry>
        </collision-->
        <collision>
            <origin rpy="1.57079632679 0 0" xyz="0.0 -0.07 -0.25"/>
            <geometry>
                <cylinder length="0.08" radius="0.04"/>
            </geometry>
        </collision>
        <inertial>
            <origin rpy="0 0 0" xyz="-0.0008 -0.0545 -0.1975"/>
            <mass value="1.51"/>
            <inertia ixx="0.0147571628275" ixy="-1.7996507882e-05" ixz="-0.000205877679383" iyy="0.0144188925719" iyz="0.00181291342366" izz="0.00178449075964"/>
        </inertial>
    </link>
    <!-- Thigh joint -->
    <joint name="RH_HFE_%d" type="revolute">
        <parent link="RH_HIP_%d"/>
        <child link="RH_THIGH_%d"/>
        <origin xyz="-0.0585                    -0.0315                    0.0"/>
        <axis xyz="0 1 0"/>
        <limit effort="80" lower="-6.28" upper="6.28" velocity="15"/>
        <dynamics damping="0.0" friction="0.0"/>
    </joint>
    <!-- Xacro:Properties -->
    <!-- [m] -->
    <!-- [Nm] -->
    <link name="RH_SHANK_%d">
        <!--collision>
            <origin rpy="0 0.9 -0.2" xyz="-0.04 0.02 -0.04"/>
            <geometry>
                <cylinder length="0.13" radius="0.015"/>
            </geometry>
        </collision-->
        <collision>
            <origin rpy="0.0 -0.34 0" xyz="-0.06 0.03 -0.18"/>
            <geometry>
                <cylinder length="0.19" radius="0.015"/>
            </geometry>
        </collision>
        <inertial>
            <origin rpy="0 0 0" xyz="-0.016355414056 0.00562219106 -0.064350437219"/>
            <mass value="0.318"/>
            <inertia ixx="0.0037693717909" ixy="-7.7334500762e-05" ixz="0.000152069372983" iyy="0.00400446467635" iyz="0.0003218356083" izz="0.000418471691904"/>
        </inertial>
    </link>
    <!-- Shank joint -->
    <joint name="RH_KFE_%d" type="revolute">
        <parent link="RH_THIGH_%d"/>
        <child link="RH_SHANK_%d"/>
        <origin xyz="-0.0 -0.111 -0.25"/>
        <axis xyz="0 1 0"/>
        <limit effort="80" lower="-6.28" upper="6.28" velocity="15"/>
        <dynamics damping="0.0" friction="0.0"/>
    </joint>
    <!-- Foot mount link -->
    <link name="RH_FOOT_MOUNT_%d"/>
    <!-- Foot mount joint / ankle -->
    <joint name="RH_ANKLE_JOINT_%d" type="fixed">
        <parent link="RH_SHANK_%d"/>
        <child link="RH_FOOT_MOUNT_%d"/>
        <origin rpy="-0.323 -0.549 0" xyz="-0.0 0.016 -0.31"/>
    </joint>
    <!-- Xacro:Properties -->
    <!-- [m] -->
    <link name="RH_FOOT_SENSOR_%d">
        <collision>
            <origin rpy="0 0 0" xyz="0.0 0.0 0"/>
            <geometry>
                <sphere radius="0.03"/>
            </geometry>
        </collision>
        <inertial>
            <origin rpy="0 0 0" xyz="5.552058e-06 -7.1133124e-05 -0.021388647779"/>
            <mass value="0.1922685"/>
            <inertia ixx="8.3086410294e-05" ixy="4.16901601e-07" ixz="-3.99054799e-07" iyy="8.2860209667e-05" iyz="3.45712252e-07" izz="8.1948124086e-05"/>
        </inertial>
    </link>
    <!-- Foot sensor joint -->
    <joint name="RH_MOUNT_TO_SENSOR_%d" type="fixed">
        <parent link="RH_FOOT_MOUNT_%d"/>
        <child link="RH_FOOT_SENSOR_%d"/>
        <origin rpy="0 0 0" xyz="0 0 0"/>
    </joint>
    <!-- Gazebo customization -->
    <gazebo reference="RH_FOOT_SENSOR">
        <kp>1000000.0</kp>
        <kd>100.0</kd>
        <mu1>0.8</mu1>
        <mu2>0.8</mu2>
    </gazebo>
    <gazebo reference="RH_MOUNT_TO_SENSOR"/>
    <!-- Foot link -->
    <link name="RH_FOOT_%d">
    </link>
    <!-- Foot joint -->
    <joint name="RH_SENSOR_TO_FOOT_%d" type="fixed">
        <parent link="RH_FOOT_SENSOR_%d"/>
        <child link="RH_FOOT_%d"/>
        <origin rpy="0 0 0" xyz="0.0 0.0 -0.0385"/>
    </joint>
    <link name="imu_link_%d">
        <collision>
            <origin rpy="0 0 0" xyz="0 0 0.011"/>
            <geometry>
                <box size="0.058 0.058 0.022"/>
            </geometry>
        </collision>
        <inertial>
            <mass value="0.05"/>
            <origin xyz="0 0 0"/>
            <inertia ixx="1.60333333333e-05" ixy="0.0" ixz="0.0" iyy="2.80333333333e-05" iyz="0.0" izz="1.60333333333e-05"/>
        </inertial>
    </link>
    <joint name="imu_joint_%d" type="fixed">
        <parent link="base_%d"/>
        <child link="imu_link_%d"/>
        <origin rpy="3.14159265359 0 0" xyz="0.0245 -0.04255 0.1857"/>
    </joint>