<robot name="2DrobotArm">
    <link name="world"/>

    <link name="link1">
        <visual>
            <origin rpy="0 0 0" xyz="0 0 0.11"/>
            <geometry>
                <cylinder length="0.2" radius="0.02"/>
            </geometry>
        </visual>
        <visual>
            <origin rpy="0 1.57079632679 0" xyz="0 0 0.3"/>
            <geometry>
                <cylinder length="0.1" radius="0.01"/>
            </geometry>
        </visual>
        <collision>
            <origin rpy="0 0 0" xyz="0 0 0.11"/>
            <geometry>
                <cylinder length="0.2" radius="0.02"/>
            </geometry>
        </collision>
    </link>

    <joint name="worldTolink1" type="fixed">
        <parent link="world"/>
        <child link="link1"/>
        <origin xyz="0 0 0"/>
    </joint>

    <link name="link2">
        <visual>
            <origin rpy="0 0 0" xyz="0 0 0.2"/>
            <geometry>
                <cylinder length="0.3" radius="0.02"/>
            </geometry>
        </visual>
        <visual>
            <origin rpy="1.57079632679 0 0" xyz="0 0 0.4"/>
            <geometry>
                <cylinder length="0.1" radius="0.01"/>
            </geometry>
        </visual>
        <collision>
            <origin rpy="0 0 0" xyz="0 0 0.2"/>
            <geometry>
                <cylinder length="0.3" radius="0.02"/>
            </geometry>
        </collision>
        <inertial>
            <origin rpy="0 0 0" xyz="0.0 0.0 0.2"/>
            <mass value="1"/>
            <inertia ixx="0.001" ixy="0" ixz="0" iyy="0.001" iyz="0" izz="0.001"/>
        </inertial>
    </link>

    <joint name="link1Tolink2" type="revolute">
        <parent link="link1"/>
        <child link="link2"/>
        <origin xyz="0 0 0.3"/>
        <axis xyz="1 0 0"/>
        <limit effort="80" lower="-6.28" upper="6.28" velocity="15"/>
    </joint>

    <link name="link3">
        <visual>
            <origin rpy="0 0 0" xyz="0 0 0.2"/>
            <geometry>
                <cylinder length="0.25" radius="0.02"/>
            </geometry>
        </visual>
        <collision>
            <origin rpy="0 0 0" xyz="0 0 0.2"/>
            <geometry>
                <cylinder length="0.25" radius="0.02"/>
            </geometry>
        </collision>
        <inertial>
            <origin rpy="0 0 0" xyz="0.0 0.0 0.2"/>
            <mass value="1"/>
            <inertia ixx="0.001" ixy="0" ixz="0" iyy="0.001" iyz="0" izz="0.001"/>
        </inertial>
    </link>

    <joint name="link2Tolink3" type="revolute">
        <parent link="link2"/>
        <child link="link3"/>
        <origin xyz="0 0 0.4"/>
        <axis xyz="0 1 0"/>
        <limit effort="80" lower="-6.28" upper="6.28" velocity="15"/>
    </joint>
</robot>
